[2016-10-31 00:53:55] WARNING [py.warnings.<module>:8] C:\Users\fndui\AppData\Local\Programs\Python\Python35-32\lib\site-packages\south\db\generic.py:9: RemovedInDjango19Warning: The django.db.backends.util module has been renamed. Use django.db.backends.utils instead.
  from django.db.backends.util import truncate_name

[2016-10-31 00:55:46] WARNING [py.warnings.<module>:8] C:\Users\fndui\AppData\Local\Programs\Python\Python35-32\lib\site-packages\south\db\generic.py:9: RemovedInDjango19Warning: The django.db.backends.util module has been renamed. Use django.db.backends.utils instead.
  from django.db.backends.util import truncate_name

[2016-10-31 01:13:07] WARNING [py.warnings.<module>:9] C:\Program Files (x86)\JetBrains\PyCharm 2016.2.3\helpers\pydev\_pydev_bundle\pydev_import_hook.py:21: RemovedInDjango19Warning: The utilities in django.db.models.loading are deprecated in favor of the new application loading system.
  module = self._system_import(name, *args, **kwargs)

[2016-10-31 01:13:52] WARNING [py.warnings.<module>:9] C:\Program Files (x86)\JetBrains\PyCharm 2016.2.3\helpers\pydev\_pydev_bundle\pydev_import_hook.py:21: RemovedInDjango19Warning: The utilities in django.db.models.loading are deprecated in favor of the new application loading system.
  module = self._system_import(name, *args, **kwargs)

[2016-10-31 01:16:56] WARNING [py.warnings.<module>:9] C:\Program Files (x86)\JetBrains\PyCharm 2016.2.3\helpers\pydev\_pydev_bundle\pydev_import_hook.py:21: RemovedInDjango19Warning: The utilities in django.db.models.loading are deprecated in favor of the new application loading system.
  module = self._system_import(name, *args, **kwargs)

[2016-10-31 01:27:53] WARNING [django.request.get_response:170] Not Found: /
[2016-10-31 01:44:13] ERROR [django.request.handle_uncaught_exception:256] Internal Server Error: /
Traceback (most recent call last):
  File "C:\Users\fndui\AppData\Local\Programs\Python\Python35-32\lib\site-packages\django\core\urlresolvers.py", line 393, in urlconf_module
    return self._urlconf_module
AttributeError: 'RegexURLResolver' object has no attribute '_urlconf_module'

During handling of the above exception, another exception occurred:

Traceback (most recent call last):
  File "C:\Users\fndui\AppData\Local\Programs\Python\Python35-32\lib\site-packages\django\core\handlers\base.py", line 119, in get_response
    resolver_match = resolver.resolve(request.path_info)
  File "C:\Users\fndui\AppData\Local\Programs\Python\Python35-32\lib\site-packages\django\core\urlresolvers.py", line 365, in resolve
    for pattern in self.url_patterns:
  File "C:\Users\fndui\AppData\Local\Programs\Python\Python35-32\lib\site-packages\django\core\urlresolvers.py", line 401, in url_patterns
    patterns = getattr(self.urlconf_module, "urlpatterns", self.urlconf_module)
  File "C:\Users\fndui\AppData\Local\Programs\Python\Python35-32\lib\site-packages\django\core\urlresolvers.py", line 395, in urlconf_module
    self._urlconf_module = import_module(self.urlconf_name)
  File "C:\Users\fndui\AppData\Local\Programs\Python\Python35-32\lib\importlib\__init__.py", line 126, in import_module
    return _bootstrap._gcd_import(name[level:], package, level)
  File "<frozen importlib._bootstrap>", line 986, in _gcd_import
  File "<frozen importlib._bootstrap>", line 969, in _find_and_load
  File "<frozen importlib._bootstrap>", line 958, in _find_and_load_unlocked
  File "<frozen importlib._bootstrap>", line 673, in _load_unlocked
  File "<frozen importlib._bootstrap_external>", line 662, in exec_module
  File "<frozen importlib._bootstrap>", line 222, in _call_with_frames_removed
  File "C:\Users\fndui\PycharmProjects\skeleton\skeleton\urls.py", line 20, in <module>
    url(r'^', include('apps.myapp.urls'))
  File "C:\Users\fndui\AppData\Local\Programs\Python\Python35-32\lib\site-packages\django\conf\urls\__init__.py", line 33, in include
    urlconf_module = import_module(urlconf_module)
  File "C:\Users\fndui\AppData\Local\Programs\Python\Python35-32\lib\importlib\__init__.py", line 126, in import_module
    return _bootstrap._gcd_import(name[level:], package, level)
  File "<frozen importlib._bootstrap>", line 986, in _gcd_import
  File "<frozen importlib._bootstrap>", line 969, in _find_and_load
  File "<frozen importlib._bootstrap>", line 958, in _find_and_load_unlocked
  File "<frozen importlib._bootstrap>", line 673, in _load_unlocked
  File "<frozen importlib._bootstrap_external>", line 662, in exec_module
  File "<frozen importlib._bootstrap>", line 222, in _call_with_frames_removed
  File "C:\Users\fndui\PycharmProjects\skeleton\apps\myapp\urls.py", line 5, in <module>
    url(r'/', views.indexView, name='index')
AttributeError: module 'apps.myapp.views' has no attribute 'indexView'
[2016-10-31 01:44:26] WARNING [django.request.get_response:170] Not Found: /
[2016-10-31 01:45:27] ERROR [django.request.handle_uncaught_exception:256] Internal Server Error: /index
Traceback (most recent call last):
  File "C:\Users\fndui\AppData\Local\Programs\Python\Python35-32\lib\site-packages\django\core\handlers\base.py", line 151, in get_response
    % (callback.__module__, view_name))
ValueError: The view apps.myapp.views.index didn't return an HttpResponse object. It returned None instead.
[2016-10-31 01:57:07] WARNING [py.warnings.__init__:260] C:\Users\fndui\AppData\Local\Programs\Python\Python35-32\lib\site-packages\django\core\management\base.py:260: RemovedInDjango19Warning: "requires_model_validation" is deprecated in favor of "requires_system_checks".
  RemovedInDjango19Warning)

